Traceback (most recent call last):
  File "/Library/Frameworks/Python.framework/Versions/3.13/lib/python3.13/site-packages/jupyter_cache/executors/utils.py", line 58, in single_nb_execution
    executenb(
    ~~~~~~~~~^
        nb,
        ^^^
    ...<4 lines>...
        **kwargs,
        ^^^^^^^^^
    )
    ^
  File "/Library/Frameworks/Python.framework/Versions/3.13/lib/python3.13/site-packages/nbclient/client.py", line 1319, in execute
    return NotebookClient(nb=nb, resources=resources, km=km, **kwargs).execute()
           ~~~~~~~~~~~~~~~~~~~~~~~~~~~~~~~~~~~~~~~~~~~~~~~~~~~~~~~~~~~~~~~~~~~^^
  File "/Users/leonardbus/Library/Python/3.13/lib/python/site-packages/jupyter_core/utils/__init__.py", line 165, in wrapped
    return loop.run_until_complete(inner)
           ~~~~~~~~~~~~~~~~~~~~~~~^^^^^^^
  File "/Library/Frameworks/Python.framework/Versions/3.13/lib/python3.13/asyncio/base_events.py", line 721, in run_until_complete
    return future.result()
           ~~~~~~~~~~~~~^^
  File "/Library/Frameworks/Python.framework/Versions/3.13/lib/python3.13/site-packages/nbclient/client.py", line 709, in async_execute
    await self.async_execute_cell(
        cell, index, execution_count=self.code_cells_executed + 1
    )
  File "/Library/Frameworks/Python.framework/Versions/3.13/lib/python3.13/site-packages/nbclient/client.py", line 1062, in async_execute_cell
    await self._check_raise_for_error(cell, cell_index, exec_reply)
  File "/Library/Frameworks/Python.framework/Versions/3.13/lib/python3.13/site-packages/nbclient/client.py", line 918, in _check_raise_for_error
    raise CellExecutionError.from_cell_and_msg(cell, exec_reply_content)
nbclient.exceptions.CellExecutionError: An error occurred while executing the following cell:
------------------
focus = focus.copy()
focus['landnaam'] = focus['geo'].map(country_names)

fig_line = px.line(focus, x='year', y='co2', color='landnaam',
                   title='Gem. COâ‚‚â€‘uitstoot nieuwe autoâ€™s (2013â€‘2023)',
                   labels=dict(year='Jaar', co2='COâ‚‚ (g/km)', landnaam='Land'))
fig_line.update_traces(mode='lines+markers')
# Convert to HTML and display
fig_line.show()

------------------


[31m---------------------------------------------------------------------------[39m
[31mNameError[39m                                 Traceback (most recent call last)
[36mCell[39m[36m [39m[32mIn[6][39m[32m, line 2[39m
[32m      1[39m focus = focus.copy()
[32m----> [39m[32m2[39m focus[[33m'[39m[33mlandnaam[39m[33m'[39m] = focus[[33m'[39m[33mgeo[39m[33m'[39m].map([43mcountry_names[49m)
[32m      4[39m fig_line = px.line(focus, x=[33m'[39m[33myear[39m[33m'[39m, y=[33m'[39m[33mco2[39m[33m'[39m, color=[33m'[39m[33mlandnaam[39m[33m'[39m,
[32m      5[39m                    title=[33m'[39m[33mGem. COâ‚‚â€‘uitstoot nieuwe autoâ€™s (2013â€‘2023)[39m[33m'[39m,
[32m      6[39m                    labels=[38;5;28mdict[39m(year=[33m'[39m[33mJaar[39m[33m'[39m, co2=[33m'[39m[33mCOâ‚‚ (g/km)[39m[33m'[39m, landnaam=[33m'[39m[33mLand[39m[33m'[39m))
[32m      7[39m fig_line.update_traces(mode=[33m'[39m[33mlines+markers[39m[33m'[39m)

[31mNameError[39m: name 'country_names' is not defined

